<?xml version="1.0"?>
<robot name="physics">

  <link name="link_x">
    <inertial>
      <mass value="0"/>
      <inertia ixx="1.0" ixy="0.0" ixz="0.0" iyy="1.0" iyz="0.0" izz="1.0"/>
    </inertial>
  </link>

  <link name="link_y">
    <inertial>
      <mass value="1"/>
      <inertia ixx="1.0" ixy="0.0" ixz="0.0" iyy="1.0" iyz="0.0" izz="1.0"/>
    </inertial>
  </link>

  <joint name="joint_x" type="prismatic">
    <axis xyz="1 0 0"/>
    <origin xyz="0.0 0.0 0.0"/>
    <parent link="link_x"/>
    <child link="link_y"/>
    <limit effort="1000.0" lower="-15" upper="15" velocity="5"/>
  </joint>

  <link name="tip">
    <visual>
      <geometry>
        <mesh filename="tip_nicer.obj" scale="1.0 1.0 1.0"/>      
      </geometry>
      <origin rpy="0 0 0" xyz="0 0 0"/>
      <material name="black">
        <color rgba="0 0 0 1"/>
      </material>
    </visual>
    <inertial>
    <origin xyz="0 0 0"/>
      <mass value="0.1"/>
      <inertia ixx="1.0" ixy="0.0" ixz="0.0" iyy="1.0" iyz="0.0" izz="1.0"/>
    </inertial>
  </link>

  <joint name="joint_y" type="prismatic">
    <axis xyz="0 1 0"/>
    <origin xyz="0.0 0.0 0"/>
    <parent link="link_y"/>
    <child link="tip"/>
    <limit effort="1000.0" lower="-15" upper="15" velocity="5"/>
  </joint>
  
</robot>